/cosma/local/Python/3.10.1/lib/python3.10/site-packages/numpy/lib/function_base.py:2246: RuntimeWarning: invalid value encountered in _integral_lookback_time (vectorized)
  outputs = ufunc(*inputs)
/cosma/local/Python/3.10.1/lib/python3.10/site-packages/numpy/lib/function_base.py:2246: RuntimeWarning: invalid value encountered in _integral_lookback_time (vectorized)
  outputs = ufunc(*inputs)
/cosma/local/Python/3.10.1/lib/python3.10/site-packages/numpy/lib/function_base.py:2246: RuntimeWarning: invalid value encountered in _integral_lookback_time (vectorized)
  outputs = ufunc(*inputs)
/cosma/local/Python/3.10.1/lib/python3.10/site-packages/numpy/lib/function_base.py:2246: RuntimeWarning: invalid value encountered in _integral_lookback_time (vectorized)
  outputs = ufunc(*inputs)
/cosma/local/Python/3.10.1/lib/python3.10/site-packages/numpy/lib/function_base.py:2246: RuntimeWarning: invalid value encountered in _integral_lookback_time (vectorized)
  outputs = ufunc(*inputs)
/cosma/local/Python/3.10.1/lib/python3.10/site-packages/numpy/lib/function_base.py:2246: RuntimeWarning: invalid value encountered in _integral_lookback_time (vectorized)
  outputs = ufunc(*inputs)
/cosma/local/Python/3.10.1/lib/python3.10/site-packages/numpy/lib/function_base.py:2246: RuntimeWarning: invalid value encountered in _integral_lookback_time (vectorized)
  outputs = ufunc(*inputs)
/cosma/local/Python/3.10.1/lib/python3.10/site-packages/numpy/lib/function_base.py:2246: RuntimeWarning: invalid value encountered in _integral_lookback_time (vectorized)
  outputs = ufunc(*inputs)
/cosma/local/Python/3.10.1/lib/python3.10/site-packages/numpy/lib/function_base.py:2246: RuntimeWarning: invalid value encountered in _integral_lookback_time (vectorized)
  outputs = ufunc(*inputs)
/cosma/local/Python/3.10.1/lib/python3.10/site-packages/numpy/lib/function_base.py:2246: RuntimeWarning: invalid value encountered in _integral_lookback_time (vectorized)
  outputs = ufunc(*inputs)
/cosma/local/Python/3.10.1/lib/python3.10/site-packages/numpy/lib/function_base.py:2246: RuntimeWarning: invalid value encountered in _integral_lookback_time (vectorized)
  outputs = ufunc(*inputs)
/cosma/local/Python/3.10.1/lib/python3.10/site-packages/numpy/lib/function_base.py:2246: RuntimeWarning: invalid value encountered in _integral_lookback_time (vectorized)
  outputs = ufunc(*inputs)
/cosma/local/Python/3.10.1/lib/python3.10/site-packages/numpy/lib/function_base.py:2246: RuntimeWarning: invalid value encountered in _integral_lookback_time (vectorized)
  outputs = ufunc(*inputs)
/cosma/local/Python/3.10.1/lib/python3.10/site-packages/numpy/lib/function_base.py:2246: RuntimeWarning: invalid value encountered in _integral_lookback_time (vectorized)
  outputs = ufunc(*inputs)
/cosma/local/Python/3.10.1/lib/python3.10/site-packages/numpy/lib/function_base.py:2246: RuntimeWarning: invalid value encountered in _integral_lookback_time (vectorized)
  outputs = ufunc(*inputs)
/cosma/local/Python/3.10.1/lib/python3.10/site-packages/numpy/lib/function_base.py:2246: RuntimeWarning: invalid value encountered in _integral_lookback_time (vectorized)
  outputs = ufunc(*inputs)
/cosma/local/Python/3.10.1/lib/python3.10/site-packages/numpy/lib/function_base.py:2246: RuntimeWarning: invalid value encountered in _integral_lookback_time (vectorized)
  outputs = ufunc(*inputs)
/cosma/local/Python/3.10.1/lib/python3.10/site-packages/numpy/lib/function_base.py:2246: RuntimeWarning: invalid value encountered in _integral_lookback_time (vectorized)
  outputs = ufunc(*inputs)
/cosma/local/Python/3.10.1/lib/python3.10/site-packages/numpy/lib/function_base.py:2246: RuntimeWarning: invalid value encountered in _integral_lookback_time (vectorized)
  outputs = ufunc(*inputs)
/cosma/local/Python/3.10.1/lib/python3.10/site-packages/numpy/lib/function_base.py:2246: RuntimeWarning: invalid value encountered in _integral_lookback_time (vectorized)
  outputs = ufunc(*inputs)
/cosma/local/Python/3.10.1/lib/python3.10/site-packages/numpy/lib/function_base.py:2246: RuntimeWarning: invalid value encountered in _integral_lookback_time (vectorized)
  outputs = ufunc(*inputs)
/cosma/local/Python/3.10.1/lib/python3.10/site-packages/numpy/lib/function_base.py:2246: RuntimeWarning: invalid value encountered in _integral_lookback_time (vectorized)
  outputs = ufunc(*inputs)
/cosma/local/Python/3.10.1/lib/python3.10/site-packages/numpy/lib/function_base.py:2246: RuntimeWarning: invalid value encountered in _integral_lookback_time (vectorized)
  outputs = ufunc(*inputs)
/cosma/local/Python/3.10.1/lib/python3.10/site-packages/numpy/lib/function_base.py:2246: RuntimeWarning: invalid value encountered in _integral_lookback_time (vectorized)
  outputs = ufunc(*inputs)
/cosma/local/Python/3.10.1/lib/python3.10/site-packages/numpy/lib/function_base.py:2246: RuntimeWarning: invalid value encountered in _integral_lookback_time (vectorized)
  outputs = ufunc(*inputs)
/cosma/local/Python/3.10.1/lib/python3.10/site-packages/numpy/lib/function_base.py:2246: RuntimeWarning: invalid value encountered in _integral_lookback_time (vectorized)
  outputs = ufunc(*inputs)
/cosma/local/Python/3.10.1/lib/python3.10/site-packages/numpy/lib/function_base.py:2246: RuntimeWarning: invalid value encountered in _integral_lookback_time (vectorized)
  outputs = ufunc(*inputs)
/cosma/local/Python/3.10.1/lib/python3.10/site-packages/numpy/lib/function_base.py:2246: RuntimeWarning: invalid value encountered in _integral_lookback_time (vectorized)
  outputs = ufunc(*inputs)
/cosma/local/Python/3.10.1/lib/python3.10/site-packages/numpy/lib/function_base.py:2246: RuntimeWarning: invalid value encountered in _integral_lookback_time (vectorized)
  outputs = ufunc(*inputs)
/cosma/local/Python/3.10.1/lib/python3.10/site-packages/numpy/lib/function_base.py:2246: RuntimeWarning: invalid value encountered in _integral_lookback_time (vectorized)
  outputs = ufunc(*inputs)
/cosma/local/Python/3.10.1/lib/python3.10/site-packages/numpy/lib/function_base.py:2246: RuntimeWarning: invalid value encountered in _integral_lookback_time (vectorized)
  outputs = ufunc(*inputs)
/cosma/local/Python/3.10.1/lib/python3.10/site-packages/numpy/lib/function_base.py:2246: RuntimeWarning: invalid value encountered in _integral_lookback_time (vectorized)
  outputs = ufunc(*inputs)
/cosma/local/Python/3.10.1/lib/python3.10/site-packages/numpy/lib/function_base.py:2246: RuntimeWarning: invalid value encountered in _integral_lookback_time (vectorized)
  outputs = ufunc(*inputs)
/cosma/local/Python/3.10.1/lib/python3.10/site-packages/numpy/lib/function_base.py:2246: RuntimeWarning: invalid value encountered in _integral_lookback_time (vectorized)
  outputs = ufunc(*inputs)
/cosma/local/Python/3.10.1/lib/python3.10/site-packages/numpy/lib/function_base.py:2246: RuntimeWarning: invalid value encountered in _integral_lookback_time (vectorized)
  outputs = ufunc(*inputs)
/cosma/local/Python/3.10.1/lib/python3.10/site-packages/numpy/lib/function_base.py:2246: RuntimeWarning: invalid value encountered in _integral_lookback_time (vectorized)
  outputs = ufunc(*inputs)
/cosma/local/Python/3.10.1/lib/python3.10/site-packages/numpy/lib/function_base.py:2246: RuntimeWarning: invalid value encountered in _integral_lookback_time (vectorized)
  outputs = ufunc(*inputs)
/cosma/local/Python/3.10.1/lib/python3.10/site-packages/numpy/lib/function_base.py:2246: RuntimeWarning: invalid value encountered in _integral_lookback_time (vectorized)
  outputs = ufunc(*inputs)
/cosma/local/Python/3.10.1/lib/python3.10/site-packages/numpy/lib/function_base.py:2246: RuntimeWarning: invalid value encountered in _integral_lookback_time (vectorized)
  outputs = ufunc(*inputs)
/cosma/local/Python/3.10.1/lib/python3.10/site-packages/numpy/lib/function_base.py:2246: RuntimeWarning: invalid value encountered in _integral_lookback_time (vectorized)
  outputs = ufunc(*inputs)
/cosma/local/Python/3.10.1/lib/python3.10/site-packages/numpy/lib/function_base.py:2246: RuntimeWarning: invalid value encountered in _integral_lookback_time (vectorized)
  outputs = ufunc(*inputs)
/cosma/local/Python/3.10.1/lib/python3.10/site-packages/numpy/lib/function_base.py:2246: RuntimeWarning: invalid value encountered in _integral_lookback_time (vectorized)
  outputs = ufunc(*inputs)
/cosma/local/Python/3.10.1/lib/python3.10/site-packages/numpy/lib/function_base.py:2246: RuntimeWarning: invalid value encountered in _integral_lookback_time (vectorized)
  outputs = ufunc(*inputs)
/cosma/local/Python/3.10.1/lib/python3.10/site-packages/numpy/lib/function_base.py:2246: RuntimeWarning: invalid value encountered in _integral_lookback_time (vectorized)
  outputs = ufunc(*inputs)
/cosma/local/Python/3.10.1/lib/python3.10/site-packages/numpy/lib/function_base.py:2246: RuntimeWarning: invalid value encountered in _integral_lookback_time (vectorized)
  outputs = ufunc(*inputs)
/cosma/local/Python/3.10.1/lib/python3.10/site-packages/numpy/lib/function_base.py:2246: RuntimeWarning: invalid value encountered in _integral_lookback_time (vectorized)
  outputs = ufunc(*inputs)
/cosma/local/Python/3.10.1/lib/python3.10/site-packages/numpy/lib/function_base.py:2246: RuntimeWarning: invalid value encountered in _integral_lookback_time (vectorized)
  outputs = ufunc(*inputs)
/cosma/local/Python/3.10.1/lib/python3.10/site-packages/numpy/lib/function_base.py:2246: RuntimeWarning: invalid value encountered in _integral_lookback_time (vectorized)
  outputs = ufunc(*inputs)
/cosma/local/Python/3.10.1/lib/python3.10/site-packages/numpy/lib/function_base.py:2246: RuntimeWarning: invalid value encountered in _integral_lookback_time (vectorized)
  outputs = ufunc(*inputs)
/cosma/local/Python/3.10.1/lib/python3.10/site-packages/numpy/lib/function_base.py:2246: RuntimeWarning: invalid value encountered in _integral_lookback_time (vectorized)
  outputs = ufunc(*inputs)
/cosma/local/Python/3.10.1/lib/python3.10/site-packages/numpy/lib/function_base.py:2246: RuntimeWarning: invalid value encountered in _integral_lookback_time (vectorized)
  outputs = ufunc(*inputs)
/cosma/local/Python/3.10.1/lib/python3.10/site-packages/numpy/lib/function_base.py:2246: RuntimeWarning: invalid value encountered in _integral_lookback_time (vectorized)
  outputs = ufunc(*inputs)
/cosma/local/Python/3.10.1/lib/python3.10/site-packages/numpy/lib/function_base.py:2246: RuntimeWarning: invalid value encountered in _integral_lookback_time (vectorized)
  outputs = ufunc(*inputs)
/cosma/local/Python/3.10.1/lib/python3.10/site-packages/numpy/lib/function_base.py:2246: RuntimeWarning: invalid value encountered in _integral_lookback_time (vectorized)
  outputs = ufunc(*inputs)
/cosma/local/Python/3.10.1/lib/python3.10/site-packages/numpy/lib/function_base.py:2246: RuntimeWarning: invalid value encountered in _integral_lookback_time (vectorized)
  outputs = ufunc(*inputs)
/cosma/local/Python/3.10.1/lib/python3.10/site-packages/numpy/lib/function_base.py:2246: RuntimeWarning: invalid value encountered in _integral_lookback_time (vectorized)
  outputs = ufunc(*inputs)
/cosma/local/Python/3.10.1/lib/python3.10/site-packages/numpy/lib/function_base.py:2246: RuntimeWarning: invalid value encountered in _integral_lookback_time (vectorized)
  outputs = ufunc(*inputs)
/cosma/local/Python/3.10.1/lib/python3.10/site-packages/numpy/lib/function_base.py:2246: RuntimeWarning: invalid value encountered in _integral_lookback_time (vectorized)
  outputs = ufunc(*inputs)
/cosma/local/Python/3.10.1/lib/python3.10/site-packages/numpy/lib/function_base.py:2246: RuntimeWarning: invalid value encountered in _integral_lookback_time (vectorized)
  outputs = ufunc(*inputs)
/cosma/local/Python/3.10.1/lib/python3.10/site-packages/numpy/lib/function_base.py:2246: RuntimeWarning: invalid value encountered in _integral_lookback_time (vectorized)
  outputs = ufunc(*inputs)
/cosma/local/Python/3.10.1/lib/python3.10/site-packages/numpy/lib/function_base.py:2246: RuntimeWarning: invalid value encountered in _integral_lookback_time (vectorized)
  outputs = ufunc(*inputs)
/cosma/local/Python/3.10.1/lib/python3.10/site-packages/numpy/lib/function_base.py:2246: RuntimeWarning: invalid value encountered in _integral_lookback_time (vectorized)
  outputs = ufunc(*inputs)
/cosma/local/Python/3.10.1/lib/python3.10/site-packages/numpy/lib/function_base.py:2246: RuntimeWarning: invalid value encountered in _integral_lookback_time (vectorized)
  outputs = ufunc(*inputs)
/cosma/local/Python/3.10.1/lib/python3.10/site-packages/numpy/lib/function_base.py:2246: RuntimeWarning: invalid value encountered in _integral_lookback_time (vectorized)
  outputs = ufunc(*inputs)
concurrent.futures.process._RemoteTraceback: 
"""
Traceback (most recent call last):
  File "/cosma/local/Python/3.10.1/lib/python3.10/concurrent/futures/process.py", line 243, in _process_worker
    r = call_item.fn(*call_item.args, **call_item.kwargs)
  File "/cosma/local/Python/3.10.1/lib/python3.10/concurrent/futures/process.py", line 202, in _process_chunk
    return [fn(*args) for args in chunk]
  File "/cosma/local/Python/3.10.1/lib/python3.10/concurrent/futures/process.py", line 202, in <listcomp>
    return [fn(*args) for args in chunk]
  File "/cosma8/data/dp004/dc-chen3/work/bin/halo-radial-profile-in-snapshot/bin/cal_halo_lum_props_by_halo_cylinder_130.py", line 112, in cal_halo_summass
    return lumdict['o7f'], lumdict['o8'], lumdict['fe17'], jointmsk, data.gas.masses, data.gas.densities, nH_densities, data.gas.temperatures, abun_to_solar[:,0], abun_to_solar[:,1], abun_to_solar[:,2], abun_to_solar[:,3], abun_to_solar[:,4], abun_to_solar[:,5], abun_to_solar[:,6], abun_to_solar[:,7], abun_to_solar[:,10], data.gas.coordinates[:,0], data.gas.coordinates[:,1], data.gas.coordinates[:,2]
IndexError: invalid index to scalar variable.
"""

The above exception was the direct cause of the following exception:

Traceback (most recent call last):
  File "/cosma8/data/dp004/dc-chen3/work/bin/halo-radial-profile-in-snapshot/bin/cal_halo_lum_props_by_halo_cylinder_130.py", line 177, in <module>
    for i, result in enumerate(executor.map(cal_halo_summass,np.array(halo_sel_ids-1, dtype = int))):
  File "/cosma/local/Python/3.10.1/lib/python3.10/concurrent/futures/process.py", line 567, in _chain_from_iterable_of_lists
    for element in iterable:
  File "/cosma/local/Python/3.10.1/lib/python3.10/concurrent/futures/_base.py", line 608, in result_iterator
    yield fs.pop().result()
  File "/cosma/local/Python/3.10.1/lib/python3.10/concurrent/futures/_base.py", line 438, in result
    return self.__get_result()
  File "/cosma/local/Python/3.10.1/lib/python3.10/concurrent/futures/_base.py", line 390, in __get_result
    raise self._exception
IndexError: invalid index to scalar variable.
